Workbook

Sheet START_HERE
A1: NORTHSTAR SPREADSHEET CLEANUP PORTFOLIO DEMO
A2: Purpose | B2: A fictional, portfolio-ready spreadsheet cleanup exercise based on the FY2025 Northstar financial report supplied by the user.
A3: Important | B3: All transaction-level sales and expense rows are SYNTHETIC allocations created to match the report's monthly and annual totals. They are not original accounting records.
A4: Source report totals | B4: Revenue $506,000; expenses $459,006; net operating profit $46,994; open receivables $66,100; open payables $12,470.
A5: Workbook tabs | B5: RAW_MESSY = intentionally inconsistent raw sample; CLEAN_TRANSACTIONS = normalized deduplicated records; MONTHLY_SUMMARY = monthly totals; P_AND_L = report category totals; AR_OPEN / AP_OPEN = open balances; BALANCE_SHEET = report snapshot; QA_CHECKS = reconciliation tests.
A6: Suggested portfolio screenshots | B6: Capture RAW_MESSY (top rows), CLEAN_TRANSACTIONS, MONTHLY_SUMMARY chart, and QA_CHECKS. Use them as before/after evidence.
A7: Suggested portfolio title | B7: Spreadsheet Cleanup & Financial Reporting Demo — FY2025 Fictional Dataset
A8: Scope note | B8: The clean transaction data is a constructed demonstration designed to reproduce reported totals, not a reconstruction of the company's actual ledger.

Sheet RAW_MESSY
A1: Amount / Value | B1: Date or Txn Date | C1: Memo / Notes | D1: Type | E1: Counterparty / Name | F1: Status | G1: Ref # | H1: Category / Account
A2: $29,555.00 | B2: Jan 08, 2025 | C2: Contractor delivery support | D2: Expense | E2: Cloudline Software | F2: recorded | G2: EXP-2501-01 | H2: COST OF SERVICES
A3: 6,400 | B3: 01/08/25 | C3: Business services delivered | D3: revenue | E3: Delta Design Studio | F3: Recorded | G3: INV-2501-01 | H3: Service revenue
A4: 1039 | B4: 11-Jan-2025 | C4: Payroll processing | D4: COST | E4: Westfield Marketing | F4: Recorded | G4: EXP-2501-02 | H4: Payroll expense
A5: USD 6,400.00 | B5: 2025/01/12 | C5: Business services delivered | D5: Income | E5: Evergreen Hospitality | F5: Recorded | G5: INV-2501-02 | H5: Service revenue
A6: $292.00 | B6: Jan-14-25 | C6: Campaign services | D6: Expense | E6: Pioneer Contractors | F6: Recorded | G6: EXP-2501-03 | H6: Marketing expense
A7: 6,400 | B7: Jan 16, 2025 | C7: Business services delivered | D7: revenue | E7: Ironwood Manufacturing | F7: Recorded | G7: INV-2501-03 | H7: Service revenue
A8: 205 | B8: 01/17/25 | C8: Office lease payment | D8: COST | E8: BrightPath Office Supply | F8: recorded | G8: EXP-2501-04 | H8: Office rent
A9: USD 2,000.00 | B9: 20-Jan-2025 | C9: Cloud platform license | D9: Spend | E9: Metro Utilities | F9: Recorded | G9: EXP-2501-05 | H9: SOFTWARE & SUBSCRIPTIONS
A10: $6,400.00 | B10: 2025/01/20 | C10: Business services delivered | D10: Revenue | E10: Juniper Food Markets | F10: Recorded | G10: INV-2501-04 | H10: Service revenue
A11: 39 | B11: Jan-23-25 | C11: Professional services | D11: expense | E11: Northline IT Services | F11: Recorded | G11: EXP-2501-06 | H11: General and administrative
A12: 6400 | B12: Jan 24, 2025 | C12: Business services delivered | D12: SALE | E12: Apex Retail Group | F12: Recorded | G12: INV-2501-05 | H12: Service revenue
A13: USD 24,380.00 | B13: 02/08/25 | C13: Project delivery costs | D13: Spend | E13: Westfield Marketing | F13: Recorded | G13: EXP-2502-01 | H13: Cost of services
A14: $7,000.00 | B14: 08-Feb-2025 | C14: Business services delivered | D14: Revenue | E14: Ironwood Manufacturing | F14: recorded | G14: INV-2502-01 | H14: Service revenue
A15: 2,060 | B15: 2025/02/11 | C15: Monthly payroll | D15: expense | E15: Pioneer Contractors | F15: Recorded | G15: EXP-2502-02 | H15: Payroll expense
A16: 7000 | B16: Feb-12-25 | C16: Business services delivered | D16: SALE | E16: Juniper Food Markets | F16: Recorded | G16: INV-2502-02 | H16: SERVICE REVENUE
A17: USD 7.00 | B17: Feb 14, 2025 | C17: Campaign services | D17: Spend | E17: BrightPath Office Supply | F17: Recorded | G17: EXP-2502-03 | H17: Marketing expense
A18: $7,000.00 | B18: 02/16/25 | C18: Business services delivered | D18: Revenue | E18: Apex Retail Group | F18: Recorded | G18: INV-2502-03 | H18: Service revenue
A20: 5,337 | B20: 17-Feb-2025 | C20: Office lease payment | D20: expense | E20: Metro Utilities | F20: Recorded | G20: EXP-2502-04 | H20: Office rent
A21: 1152 | B21: 2025/02/20 | C21: Reporting tools | D21: COST | E21: Northline IT Services | F21: recorded | G21: EXP-2502-05 | H21: Software and subscriptions
A22: USD 7,000.00 | B22: Feb-20-25 | C22: Business services delivered | D22: Income | E22: Blue Oak Medical | F22: Recorded | G22: INV-2502-04 | H22: Service revenue
A23: $1,699.00 | B23: Feb 23, 2025 | C23: General business expense | D23: Expense | E23: Cloudline Software | F23: Recorded | G23: EXP-2502-06 | H23: General & administrative
A24: 7,000 | B24: 02/24/25 | C24: Business services delivered | D24: revenue | E24: Frontier Learning Co. | F24: Recorded | G24: INV-2502-05 | H24: SERVICE REVENUE
A25: 15240 | B25: 08-Mar-2025 | C25: Client service materials | D25: COST | E25: Pioneer Contractors | F25: Recorded | G25: EXP-2503-01 | H25: Cost of services
A26: USD 7,400.00 | B26: 2025/03/08 | C26: Business services delivered | D26: Income | E26: Apex Retail Group | F26: Recorded | G26: INV-2503-01 | H26: Service revenue
A27: $14,047.00 | B27: Mar-11-25 | C27: Payroll processing | D27: Expense | E27: BrightPath Office Supply | F27: recorded | G27: EXP-2503-02 | H27: Payroll expense
A28: 7,400 | B28: Mar 12, 2025 | C28: Business services delivered | D28: revenue | E28: Blue Oak Medical | F28: Recorded | G28: INV-2503-02 | H28: Service revenue
A29: 1166 | B29: 03/14/25 | C29: Digital advertising | D29: COST | E29: Metro Utilities | F29: Recorded | G29: EXP-2503-03 | H29: Marketing expense
A30: USD 7,400.00 | B30: 16-Mar-2025 | C30: Business services delivered | D30: Income | E30: Frontier Learning Co. | F30: Recorded | G30: INV-2503-03 | H30: Service revenue
A31: $413.00 | B31: 2025/03/17 | C31: Workspace rent | D31: Expense | E31: Northline IT Services | F31: Recorded | G31: EXP-2503-04 | H31: OFFICE RENT
A32: 1,856 | B32: Mar-20-25 | C32: Cloud platform license | D32: expense | E32: Cloudline Software | F32: Recorded | G32: EXP-2503-05 | H32: Software & subscriptions
A33: 7400 | B33: Mar 20, 2025 | C33: Business services delivered | D33: SALE | E33: Granite Property Partners | F33: recorded | G33: INV-2503-04 | H33: Service revenue
A34: USD 2,427.00 | B34: 03/23/25 | C34: Office administration | D34: Spend | E34: Westfield Marketing | F34: Recorded | G34: EXP-2503-06 | H34: General & administrative
A35: $7,400.00 | B35: 24-Mar-2025 | C35: Business services delivered | D35: Revenue | E35: Harborview Consulting | F35: Recorded | G35: INV-2503-05 | H35: Service revenue
A36: 22,674 | B36: 2025/04/08 | C36: Contractor delivery support | D36: expense | E36: BrightPath Office Supply | F36: Recorded | G36: EXP-2504-01 | H36: Cost of services
A37: 7600 | B37: Apr-08-25 | C37: Business services delivered | D37: SALE | E37: Frontier Learning Co. | F37: Recorded | G37: INV-2504-01 | H37: Service revenue
A38: USD 6,044.00 | B38: Apr 11, 2025 | C38: Staff compensation | D38: Spend | E38: Metro Utilities | F38: Recorded | G38: EXP-2504-02 | H38: PAYROLL EXPENSE
A39: $7,600.00 | B39: 04/12/25 | C39: Business services delivered | D39: Revenue | E39: Granite Property Partners | F39: recorded | G39: INV-2504-02 | H39: Service revenue
A40: 220 | B40: 14-Apr-2025 | C40: Marketing materials | D40: expense | E40: Northline IT Services | F40: Recorded | G40: EXP-2504-03 | H40: Marketing expense
A41: 7600 | B41: 2025/04/16 | C41: Business services delivered | D41: SALE | E41: Harborview Consulting | F41: Recorded | G41: INV-2504-03 | H41: Service revenue
...

Sheet CLEAN_TRANSACTIONS
A1: Transaction Date | B1: Month | C1: Type | D1: Counterparty | E1: Category | F1: Description | G1: Amount (USD) | H1: Reference | I1: Record Status
A2: 45665 | B2: Jan | C2: Expense | D2: Cloudline Software | E2: Cost of services | F2: Contractor delivery support | G2: 29555 | H2: EXP-2501-01 | I2: Included
A3: 45665 | B3: Jan | C3: Revenue | D3: Delta Design Studio | E3: Service revenue | F3: Business services delivered | G3: 6400 | H3: INV-2501-01 | I3: Included
A4: 45668 | B4: Jan | C4: Expense | D4: Westfield Marketing | E4: Payroll expense | F4: Payroll processing | G4: 1039 | H4: EXP-2501-02 | I4: Included
A5: 45669 | B5: Jan | C5: Revenue | D5: Evergreen Hospitality | E5: Service revenue | F5: Business services delivered | G5: 6400 | H5: INV-2501-02 | I5: Included
A6: 45671 | B6: Jan | C6: Expense | D6: Pioneer Contractors | E6: Marketing expense | F6: Campaign services | G6: 292 | H6: EXP-2501-03 | I6: Included
A7: 45673 | B7: Jan | C7: Revenue | D7: Ironwood Manufacturing | E7: Service revenue | F7: Business services delivered | G7: 6400 | H7: INV-2501-03 | I7: Included
A8: 45674 | B8: Jan | C8: Expense | D8: BrightPath Office Supply | E8: Office rent | F8: Office lease payment | G8: 205 | H8: EXP-2501-04 | I8: Included
A9: 45677 | B9: Jan | C9: Expense | D9: Metro Utilities | E9: Software & subscriptions | F9: Cloud platform license | G9: 2000 | H9: EXP-2501-05 | I9: Included
A10: 45677 | B10: Jan | C10: Revenue | D10: Juniper Food Markets | E10: Service revenue | F10: Business services delivered | G10: 6400 | H10: INV-2501-04 | I10: Included
A11: 45680 | B11: Jan | C11: Expense | D11: Northline IT Services | E11: General & administrative | F11: Professional services | G11: 39 | H11: EXP-2501-06 | I11: Included
A12: 45681 | B12: Jan | C12: Revenue | D12: Apex Retail Group | E12: Service revenue | F12: Business services delivered | G12: 6400 | H12: INV-2501-05 | I12: Included
A13: 45696 | B13: Feb | C13: Expense | D13: Westfield Marketing | E13: Cost of services | F13: Project delivery costs | G13: 24380 | H13: EXP-2502-01 | I13: Included
... A132: 46015 | B132: Dec | C132: Revenue | D132: Maple Ridge Services | E132: Service revenue | F132: Business services delivered | G132: 10400 | H132: INV-2512-05 | I132: Included

Sheet MONTHLY_SUMMARY
A1: Month | B1: Revenue (USD) | C1: Expenses (USD) | D1: Net Profit (USD) | E1: Profit Margin
A2: 45658 | B2: =SUMIFS(CLEAN_TRANSACTIONS!$G:$G,CLEAN_TRANSACTIONS!$B:$B,TEXT(A2,"mmm"),CLEAN_TRANSACTIONS!$C:$C,"Revenue") -> 32000 | C2: =SUMIFS(CLEAN_TRANSACTIONS!$G:$G,CLEAN_TRANSACTIONS!$B:$B,TEXT(A2,"mmm"),CLEAN_TRANSACTIONS!$C:$C,"Expense") -> 33130 | D2: =B2-C2 -> -1130 | E2: =IFERROR(D2/B2,0) -> -0.0353125
A3: 45689 | B3: =SUMIFS(CLEAN_TRANSACTIONS!$G:$G,CLEAN_TRANSACTIONS!$B:$B,TEXT(A3,"mmm"),CLEAN_TRANSACTIONS!$C:$C,"Revenue") -> 35000 | C3: =SUMIFS(CLEAN_TRANSACTIONS!$G:$G,CLEAN_TRANSACTIONS!$B:$B,TEXT(A3,"mmm"),CLEAN_TRANSACTIONS!$C:$C,"Expense") -> 34635 | D3: =B3-C3 -> 365 | E3: =IFERROR(D3/B3,0) -> 0.010428571
A4: 45717 | B4: =SUMIFS(CLEAN_TRANSACTIONS!$G:$G,CLEAN_TRANSACTIONS!$B:$B,TEXT(A4,"mmm"),CLEAN_TRANSACTIONS!$C:$C,"Revenue") -> 37000 | C4: =SUMIFS(CLEAN_TRANSACTIONS!$G:$G,CLEAN_TRANSACTIONS!$B:$B,TEXT(A4,"mmm"),CLEAN_TRANSACTIONS!$C:$C,"Expense") -> 35149 | D4: =B4-C4 -> 1851 | E4: =IFERROR(D4/B4,0) -> 0.050027027
A5: 45748 | B5: =SUMIFS(CLEAN_TRANSACTIONS!$G:$G,CLEAN_TRANSACTIONS!$B:$B,TEXT(A5,"mmm"),CLEAN_TRANSACTIONS!$C:$C,"Revenue") -> 38000 | C5: =SUMIFS(CLEAN_TRANSACTIONS!$G:$G,CLEAN_TRANSACTIONS!$B:$B,TEXT(A5,"mmm"),CLEAN_TRANSACTIONS!$C:$C,"Expense") -> 36604 | D5: =B5-C5 -> 1396 | E5: =IFERROR(D5/B5,0) -> 0.036736842
A6: 45778 | B6: =SUMIFS(CLEAN_TRANSACTIONS!$G:$G,CLEAN_TRANSACTIONS!$B:$B,TEXT(A6,"mmm"),CLEAN_TRANSACTIONS!$C:$C,"Revenue") -> 40000 | C6: =SUMIFS(CLEAN_TRANSACTIONS!$G:$G,CLEAN_TRANSACTIONS!$B:$B,TEXT(A6,"mmm"),CLEAN_TRANSACTIONS!$C:$C,"Expense") -> 36475 | D6: =B6-C6 -> 3525 | E6: =IFERROR(D6/B6,0) -> 0.088125
A7: 45809 | B7: =SUMIFS(CLEAN_TRANSACTIONS!$G:$G,CLEAN_TRANSACTIONS!$B:$B,TEXT(A7,"mmm"),CLEAN_TRANSACTIONS!$C:$C,"Revenue") -> 42000 | C7: =SUMIFS(CLEAN_TRANSACTIONS!$G:$G,CLEAN_TRANSACTIONS!$B:$B,TEXT(A7,"mmm"),CLEAN_TRANSACTIONS!$C:$C,"Expense") -> 37982 | D7: =B7-C7 -> 4018 | E7: =IFERROR(D7/B7,0) -> 0.095666667
A8: 45839 | B8: =SUMIFS(CLEAN_TRANSACTIONS!$G:$G,CLEAN_TRANSACTIONS!$B:$B,TEXT(A8,"mmm"),CLEAN_TRANSACTIONS!$C:$C,"Revenue") -> 43000 | C8: =SUMIFS(CLEAN_TRANSACTIONS!$G:$G,CLEAN_TRANSACTIONS!$B:$B,TEXT(A8,"mmm"),CLEAN_TRANSACTIONS!$C:$C,"Expense") -> 38511 | D8: =B8-C8 -> 4489 | E8: =IFERROR(D8/B8,0) -> 0.10439535
A9: 45870 | B9: =SUMIFS(CLEAN_TRANSACTIONS!$G:$G,CLEAN_TRANSACTIONS!$B:$B,TEXT(A9,"mmm"),CLEAN_TRANSACTIONS!$C:$C,"Revenue") -> 44500 | C9: =SUMIFS(CLEAN_TRANSACTIONS!$G:$G,CLEAN_TRANSACTIONS!$B:$B,TEXT(A9,"mmm"),CLEAN_TRANSACTIONS!$C:$C,"Expense") -> 39806 | D9: =B9-C9 -> 4694 | E9: =IFERROR(D9/B9,0) -> 0.10548315
A10: 45901 | B10: =SUMIFS(CLEAN_TRANSACTIONS!$G:$G,CLEAN_TRANSACTIONS!$B:$B,TEXT(A10,"mmm"),CLEAN_TRANSACTIONS!$C:$C,"Revenue") -> 46000 | C10: =SUMIFS(CLEAN_TRANSACTIONS!$G:$G,CLEAN_TRANSACTIONS!$B:$B,TEXT(A10,"mmm"),CLEAN_TRANSACTIONS!$C:$C,"Expense") -> 39715 | D10: =B10-C10 -> 6285 | E10: =IFERROR(D10/B10,0) -> 0.13663043
A11: 45931 | B11: =SUMIFS(CLEAN_TRANSACTIONS!$G:$G,CLEAN_TRANSACTIONS!$B:$B,TEXT(A11,"mmm"),CLEAN_TRANSACTIONS!$C:$C,"Revenue") -> 47500 | C11: =SUMIFS(CLEAN_TRANSACTIONS!$G:$G,CLEAN_TRANSACTIONS!$B:$B,TEXT(A11,"mmm"),CLEAN_TRANSACTIONS!$C:$C,"Expense") -> 40810 | D11: =B11-C11 -> 6690 | E11: =IFERROR(D11/B11,0) -> 0.14084211
A12: 45962 | B12: =SUMIFS(CLEAN_TRANSACTIONS!$G:$G,CLEAN_TRANSACTIONS!$B:$B,TEXT(A12,"mmm"),CLEAN_TRANSACTIONS!$C:$C,"Revenue") -> 49000 | C12: =SUMIFS(CLEAN_TRANSACTIONS!$G:$G,CLEAN_TRANSACTIONS!$B:$B,TEXT(A12,"mmm"),CLEAN_TRANSACTIONS!$C:$C,"Expense") -> 42073 | D12: =B12-C12 -> 6927 | E12: =IFERROR(D12/B12,0) -> 0.14136735
A13: 45992 | B13: =SUMIFS(CLEAN_TRANSACTIONS!$G:$G,CLEAN_TRANSACTIONS!$B:$B,TEXT(A13,"mmm"),CLEAN_TRANSACTIONS!$C:$C,"Revenue") -> 52000 | C13: =SUMIFS(CLEAN_TRANSACTIONS!$G:$G,CLEAN_TRANSACTIONS!$B:$B,TEXT(A13,"mmm"),CLEAN_TRANSACTIONS!$C:$C,"Expense") -> 44116 | D13: =B13-C13 -> 7884 | E13: =IFERROR(D13/B13,0) -> 0.15161538
A14: FY2025 Total | B14: =SUM(B2:B13) -> 506000 | C14: =SUM(C2:C13) -> 459006 | D14: =SUM(D2:D13) -> 46994 | E14: =IFERROR(D14/B14,0) -> 0.092873518

Sheet P_AND_L
A1: Account | B1: FY2025 (USD) | C1: Share of Revenue
A2: Service revenue | B2: =SUMIFS(CLEAN_TRANSACTIONS!$G:$G,CLEAN_TRANSACTIONS!$C:$C,"Revenue",CLEAN_TRANSACTIONS!$E:$E,"Service revenue") -> 506000 | C2: 1
A3: Cost of services | B3: =SUMIFS(CLEAN_TRANSACTIONS!$G:$G,CLEAN_TRANSACTIONS!$C:$C,"Expense",CLEAN_TRANSACTIONS!$E:$E,"Cost of services") -> 151456 | C3: 0.29932016
A4: Payroll expense | B4: =SUMIFS(CLEAN_TRANSACTIONS!$G:$G,CLEAN_TRANSACTIONS!$C:$C,"Expense",CLEAN_TRANSACTIONS!$E:$E,"Payroll expense") -> 183550 | C4: 0.36274704
A5: Marketing expense | B5: =SUMIFS(CLEAN_TRANSACTIONS!$G:$G,CLEAN_TRANSACTIONS!$C:$C,"Expense",CLEAN_TRANSACTIONS!$E:$E,"Marketing expense") -> 33200 | C5: 0.065612648
A6: Office rent | B6: =SUMIFS(CLEAN_TRANSACTIONS!$G:$G,CLEAN_TRANSACTIONS!$C:$C,"Expense",CLEAN_TRANSACTIONS!$E:$E,"Office rent") -> 50400 | C6: 0.099604743
A7: Software & subscriptions | B7: =SUMIFS(CLEAN_TRANSACTIONS!$G:$G,CLEAN_TRANSACTIONS!$C:$C,"Expense",CLEAN_TRANSACTIONS!$E:$E,"Software & subscriptions") -> 15200 | C7: 0.030039526
A8: General & administrative | B8: =SUMIFS(CLEAN_TRANSACTIONS!$G:$G,CLEAN_TRANSACTIONS!$C:$C,"Expense",CLEAN_TRANSACTIONS!$E:$E,"General & administrative") -> 25200 | C8: 0.049802372
A9: Total revenue | B9: =SUM(B3:B3) -> 151456
A10: Total operating expenses | B10: =SUM(B3:B8) -> 459006 | C10: 0.90712648
A11: Net operating profit | B11: =B2-B10 -> 46994 | C11: 0.092873518

Sheet AR_OPEN
A1: Customer | B1: Due Date (as reported) | C1: Open Balance (USD) | D1: Status
A2: Cedar Peak Logistics | B2: 45713 | C2: 3200 | D2: Overdue
A3: Delta Design Studio | B3: 45722 | C3: 4100 | D3: Overdue
A4: Evergreen Hospitality | B4: 45731 | C4: 2750 | D4: Overdue
A5: Ironwood Manufacturing | B5: 45767 | C5: 4800 | D5: Overdue
A6: Juniper Food Markets | B6: 45776 | C6: 2250 | D6: Overdue
A7: Apex Retail Group | B7: 45803 | C7: 1850 | D7: Overdue
A8: Blue Oak Medical | B8: 45812 | C8: 2400 | D8: Overdue
A9: Frontier Learning Co. | B9: 45848 | C9: 5600 | D9: Overdue
A10: Granite Property Partners | B10: 45857 | C10: 1950 | D10: Overdue
A11: Harborview Consulting | B11: 45866 | C11: 3650 | D11: Overdue
A12: Keystone Wellness | B12: 45893 | C12: 6100 | D12: Overdue
A13: Apex Retail Group | B13: 45911 | C13: 1850 | D13: Overdue
... A19: Keystone Wellness | B19: 46001 | C19: 6100 | D19: Overdue

Sheet AP_OPEN
A1: Supplier | B1: Due Date (as reported) | C1: Open Balance (USD) | D1: Status
A2: Cloudline Software | B2: 45691 | C2: 450 | D2: Overdue
A3: Westfield Marketing | B3: 45735 | C3: 1950 | D3: Overdue
A4: Pioneer Contractors | B4: 45779 | C4: 2100 | D4: Overdue
A5: Cloudline Software | B5: 45823 | C5: 2850 | D5: Overdue
A6: Westfield Marketing | B6: 45867 | C6: 620 | D6: Overdue
A7: Pioneer Contractors | B7: 45911 | C7: 450 | D7: Overdue
A8: Cloudline Software | B8: 45955 | C8: 1950 | D8: Overdue
A9: Westfield Marketing | B9: 45999 | C9: 2100 | D9: Overdue

Sheet BALANCE_SHEET
A1: Metric | B1: FY2025 / As of Dec 31, 2025 (USD)
A2: Total assets | B2: 221500
A3: Total liabilities | B3: 42870
A4: Total equity | B4: 178630
A5: Liabilities + equity | B5: =B3+B4 -> 221500
A6: Balance difference | B6: =B2-B5 -> 0
A7: Report balance difference | B7: 0
A9: Account | B9: Amount (USD)
A10: Cash and cash equivalents | B10: 48500
A11: Accounts receivable | B11: 66100
A12: Inventory / supplies | B12: 12400
A13: Prepaid expenses | B13: 6500
A14: Equipment, net | B14: 58000
A15: Other assets | B15: 30000
A16: Total assets | B16: 221500
A17: Accounts payable | B17: 12470
A18: Accrued payroll | B18: 8400
A19: Taxes payable | B19: 5000
A20: Deferred revenue | B20: 7000
A21: Other liabilities | B21: 10000
... A27: Assets − liabilities − equity | B27: 0

Sheet QA_CHECKS
A1: Check | B1: Expected / Source Value | C1: Calculated / Detail Value | D1: Difference | E1: Status | F1: Explanation
A2: FY2025 revenue | B2: 506000 | C2: =SUMIFS(CLEAN_TRANSACTIONS!$G:$G,CLEAN_TRANSACTIONS!$C:$C,"Revenue") -> 506000 | D2: =C2-B2 -> 0 | E2: =IF(D2=0,"PASS","REVIEW") -> PASS | F2: Synthetic clean transaction lines must sum to report revenue.
A3: FY2025 expenses | B3: 459006 | C3: =SUMIFS(CLEAN_TRANSACTIONS!$G:$G,CLEAN_TRANSACTIONS!$C:$C,"Expense") -> 459006 | D3: =C3-B3 -> 0 | E3: =IF(D3=0,"PASS","REVIEW") -> PASS | F3: Synthetic clean transaction lines must sum to report expenses.
A4: FY2025 net profit | B4: 46994 | C4: =B2-B3 -> 46994 | D4: =C4-B4 -> 0 | E4: =IF(D4=0,"PASS","REVIEW") -> PASS | F4: Revenue less expenses.
A5: Open payables | B5: 12470 | C5: =SUM(AP_OPEN!C:C) -> 12470 | D5: =C5-B5 -> 0 | E5: =IF(D5=0,"PASS","REVIEW") -> PASS | F5: Listed supplier bills match the report headline.
A6: Open receivables | B6: 66100 | C6: =SUM(AR_OPEN!C:C) -> 66100 | D6: =C6-B6 -> 0 | E6: =IF(D6=0,"PASS","REVIEW") -> PASS | F6: Listed customer balances should match the report headline.
A7: Balance sheet equation | B7: 0 | C7: =BALANCE_SHEET!B6 -> 0 | D7: =C7-B7 -> 0 | E7: =IF(D7=0,"PASS","REVIEW") -> PASS | F7: Assets should equal liabilities plus equity.
